Workbook
Name Sale_Date: 'Assumptions'!$D$10
Name Gross_Sale_Price: 'Assumptions'!$D$14
Name Selling_Costs: 'Assumptions'!$D$15
Name Debt_Remaining: 'Assumptions'!$D$16
Name Cash_Equity_Consideration: 'Assumptions'!$D$17
Name Basis_Bridge: 'Assumptions'!$D$19
Name Installment_Rate: 'Assumptions'!$D$34
Name CA_Withholding_Rate: 'Assumptions'!$D$35
Name Assumed_Liabilities: 'Assumptions'!$D$37
Name Assumption_Section_1245: 'Assumptions'!$D$25
Name Assumption_Section_291: 'Assumptions'!$D$26
Name Assumption_Unrecaptured_1250: 'Assumptions'!$D$27
Name Assumption_Residual_1231: 'Assumptions'!$D$28
Name Model_As_Of: 'Assumptions'!$D$6
Name Adjusted_Tax_Basis: 'Tax Basis'!$J$88
Name Direct_Sale_Total_Gain: 'Direct Sale'!$H$44
Name Section_1245_Recapture: 'Direct Sale'!$H$35
Name Section_291_Income: 'Direct Sale'!$H$36
Name Unrecaptured_1250_Gain: 'Direct Sale'!$H$37
Name Residual_1231_Gain: 'Direct Sale'!$H$38
Name Installment_Contract_Price: 'Installment Sale'!$H$14
Name Installment_Eligible_Gain: 'Installment Sale'!$H$15
Name Partnership_Outside_Basis: 'Equity Transfer'!$H$20
Name Partnership_Total_Gain: 'Equity Transfer'!$H$36
Name LA_DTT_Exposure: 'LA Transfer Tax'!$F$27

Sheet Structure Comparison
A1: ADC Fairfax & 3rd Disposal Tax Model — Structure Comparison
A2: Agree Realty Corporation | Fairfax & 3rd Retail Center | September 30, 2025 | Executive decision view for the Investment Committee
A7: Metric / Criterion | B7: Weight | C7: Direct Asset Sale | D7: Partnership Interest Transfer | E7: Installment Sale | F7: Direct Score | G7: Equity Score | H7: Installment Score | I7: Review Note
A8: Federal taxable gain | C8: ='Direct Sale'!$H$44 | D8: ='Equity Transfer'!$H$36 | E8: ='Direct Sale'!$H$44 | I8: Lower is preferable; equity transfer includes liability relief.
A9: 2025 current-year gain | C9: ='Direct Sale'!$H$44 | D9: ='Equity Transfer'!$H$36 | E9: ='Installment Sale'!$J$29 | I9: Installment structure defers eligible gain.
A10: Deferred eligible gain | C10: 0 | D10: 0 | E10: ='Installment Sale'!$K$29 | I10: Deferred gain remains subject to future collection.
A11: Ordinary-income component | C11: ='Direct Sale'!$H$35+'Direct Sale'!$H$36 | D11: ='Equity Transfer'!$H$31 | E11: ='Installment Sale'!$I$29 | I11: Recapture is recognized in full in 2025.
A12: Los Angeles documentary transfer tax | C12: ='LA Transfer Tax'!$F$27 | D12: ='LA Transfer Tax'!$F$28 | E12: ='LA Transfer Tax'!$F$27 | I12: County and City of Los Angeles rates modeled at $5.60 per $1,000.
A14: Qualitative Decision Scorecard
A15: Criterion | B15: Weight | C15: Direct Asset Sale | D15: Partnership Interest Transfer | E15: Installment Sale | F15: Direct Score | G15: Equity Score | H15: Installment Score | I15: Review Note
A16: Tax deferral / cash timing | B16: 0.2 | C16: 2 | D16: 3 | E16: 5 | F16: =IF($B16="","",$B16*C16) | G16: =IF($B16="","",$B16*D16) | H16: =IF($B16="","",$B16*E16) | I16: Installment provides the strongest deferral.
A17: Federal tax simplicity | B17: 0.15 | C17: 4 | D17: 2 | E17: 2 | F17: =IF($B17="","",$B17*C17) | G17: =IF($B17="","",$B17*D17) | H17: =IF($B17="","",$B17*E17) | I17: Direct deed is operationally familiar.
A18: Buyer marketability | B18: 0.15 | C18: 4 | D18: 3 | E18: 2 | F18: =IF($B18="","",$B18*C18) | G18: =IF($B18="","",$B18*D18) | H18: =IF($B18="","",$B18*E18) | I18: Equity transfer narrows buyer pool.
A19: Transfer-tax efficiency | B19: 0.1 | C19: 2 | D19: 2 | E19: 2 | F19: =IF($B19="","",$B19*C19) | G19: =IF($B19="","",$B19*D19) | H19: =IF($B19="","",$B19*E19) | I19: Both direct and control-change exposures modeled.
A20: Financing and liquidity | B20: 0.1 | C20: 4 | D20: 3 | E20: 2 | F20: =IF($B20="","",$B20*C20) | G20: =IF($B20="","",$B20*D20) | H20: =IF($B20="","",$B20*E20) | I20: Installment note creates collection risk.
A21: Execution certainty | B21: 0.1 | C21: 4 | D21: 2 | E21: 2 | F21: =IF($B21="","",$B21*C21) | G21: =IF($B21="","",$B21*D21) | H21: =IF($B21="","",$B21*E21) | I21: Legal-entity and withholding diligence remain open.
A22: Recapture transparency | B22: 0.1 | C22: 4 | D22: 3 | E22: 3 | F22: =IF($B22="","",$B22*C22) | G22: =IF($B22="","",$B22*D22) | H22: =IF($B22="","",$B22*E22) | I22: All structures retain ordinary-income analysis.
A23: Accounting / reporting burden | B23: 0.05 | C23: 4 | D23: 2 | E23: 2 | F23: =IF($B23="","",$B23*C23) | G23: =IF($B23="","",$B23*D23) | H23: =IF($B23="","",$B23*E23) | I23: Installment requires long-tail tracking.
A24: Legal and withholding risk | B24: 0.05 | C24: 3 | D24: 2 | E24: 2 | F24: =IF($B24="","",$B24*C24) | G24: =IF($B24="","",$B24*D24) | H24: =IF($B24="","",$B24*E24) | I24: Review 1446(f), FIRPTA, and FTB release process.
A25: Total weighted score | C25: =SUM(F16:F24) | D25: =SUM(G16:G24) | E25: =SUM(H16:H24)
A28: Structuring Recommendation
A29: Recommended structure | B29: Installment Sale
A30: Recommendation bridge | B30: Installment Sale produces $3,935,308.98 of 2025 recognized gain and $5,884,887.52 of deferred eligible gain, subject to buyer credit and FTB withholding-release diligence.
A31: Direct-sale alternative | B31: Direct Asset Sale produces $9,820,196.50 of federal taxable gain, including $1,107,955.00 section 1245 ordinary recapture, $865,724.80 section 291 ordinary income, $3,462,899.20 unrecaptured section 1250 gain, and $4,383,617.50 residual section 1231 gain.
A32: Equity-transfer alternative | B32: Partnership Interest Transfer produces $10,850,640.00 of federal gain, including $1,248,775.00 section 751 ordinary income and $9,601,865.00 section 741 capital gain; it does not eliminate depreciation-related ordinary income.
A33: Committee action | B33: Approve continued installment-sale diligence; require transaction counsel confirmation of California withholding release, buyer credit support, and section 1446(f)/FIRPTA status before signing.
A34: Model status | B34: Review-ready planning model; not a tax opinion and not a public filing disclosure.

Sheet Assumptions
A1: ADC Fairfax & 3rd Disposal Tax Model — Assumptions
A2: Agree Realty Corporation (NYSE: ADC) | Fairfax & 3rd Retail Center | Proposed closing September 30, 2025 | Base-case inputs in light gray; yellow denotes review.
A4: Controlled Input Register
A5: Assumption ID | B5: Category | C5: Assumption | D5: Value | E5: Unit / Format | F5: Case | G5: Source / Authority | H5: Source Date | I5: Status | J5: Reviewer
A6: CTRL-01 | B6: Control | C6: Model as-of date | D6: 45930 | E6: date | F6: Base | G6: Management representation | H6: 45922 | I6: Confirmed | J6: Sarah Chen, CPA
A7: CTRL-02 | B7: Control | C7: Tax planning period | D7: 2025-Q3 | E7: period | F7: Base | G7: Investment Committee planning pack | H7: 45918 | I7: Confirmed | J7: Michael Donovan
A8: TXN-01 | B8: Property | C8: Disposition property | D8: Fairfax & 3rd Retail Center, Los Angeles, California | E8: text | F8: Base | G8: Management representation | H8: 45922 | I8: Confirmed | J8: Sarah Chen, CPA
A9: TXN-02 | B9: Property | C9: Property-owning partnership | D9: ADC Fairfax Retail Partners LP | E9: text | F9: Base | G9: Legal entity register | H9: 45919 | I9: Confirmed | J9: Priya Raman
A10: TXN-03 | B10: Transaction | C10: Proposed closing date | D10: 45930 | E10: date | F10: Base | G10: Executed term sheet draft | H10: 45918 | I10: Confirmed | J10: Michael Donovan
A11: TXN-04 | B11: Transaction | C11: Taxpayer | D11: Agree Realty Corporation (NYSE: ADC) | E11: text | F11: Base | G11: 2024 Annual Report | H11: 45717 | I11: Confirmed | J11: Elena Brooks
A12: TXN-05 | B12: Transaction | C12: Taxpayer headquarters | D12: Royal Oak, Michigan | E12: text | F12: Base | G12: 2024 Annual Report | H12: 45717 | I12: Confirmed | J12: Elena Brooks
A13: TXN-06 | B13: Transaction | C13: Reporting currency | D13: U.S. dollars | E13: text | F13: Base | G13: Model convention | H13: 45918 | I13: Confirmed | J13: Sarah Chen, CPA
A14: SALE-01 | B14: Transaction | C14: Gross selling price | D14: 28735000 | E14: USD | F14: Base | G14: Executed term sheet draft | H14: 45918 | I14: Confirmed | J14: Michael Donovan
A15: SALE-02 | B15: Transaction | C15: Selling costs | D15: 387922.5 | E15: USD | F15: Base | G15: Broker and legal estimate | H15: 45921 | I15: Preliminary | J15: Priya Raman
A16: SALE-03 | B16: Transaction | C16: Debt remaining / liens | D16: 8425000 | E16: USD | F16: Base | G16: Debt payoff letter draft | H16: 45920 | I16: Preliminary | J16: Michael Donovan
A17: SALE-04 | B17: Transaction | C17: Cash equity consideration | D17: 20310000 | E17: USD | F17: Base | G17: Equity term sheet draft | H17: 45918 | I17: Confirmed | J17: Michael Donovan
A18: SALE-05 | B18: Transaction | C18: Installment closing principal | D18: 7183750 | E18: USD | F18: Base | G18: Seller note term sheet | H18: 45920 | I18: Preliminary | J18: Priya Raman
A19: BASIS-01 | B19: Federal Tax | C19: Tax basis bridge to transaction basis | D19: 3158361 | E19: USD | F19: Base | G19: Tax basis reconciliation | H19: 45922 | I19: Review | J19: Sarah Chen, CPA
A20: BASIS-02 | B20: Federal Tax | C20: Original land basis | D20: 5814250 | E20: USD | F20: Base | G20: Fixed asset ledger | H20: 45922 | I20: Confirmed | J20: Sarah Chen, CPA
A21: BASIS-03 | B21: Federal Tax | C21: Original building basis | D21: 14962480 | E21: USD | F21: Base | G21: Fixed asset ledger | H21: 45922 | I21: Confirmed | J21: Sarah Chen, CPA
A22: BASIS-04 | B22: Federal Tax | C22: Capitalized qualified improvements | D22: 3186730 | E22: USD | F22: Base | G22: Capital project ledger | H22: 45922 | I22: Preliminary | J22: Sarah Chen, CPA
A23: BASIS-05 | B23: Federal Tax | C23: Accumulated building depreciation | D23: 4328624 | E23: USD | F23: Base | G23: Fixed asset ledger | H23: 45922 | I23: Confirmed | J23: Sarah Chen, CPA
A24: BASIS-06 | B24: Federal Tax | C24: Accumulated improvement depreciation | D24: 1107955 | E24: USD | F24: Base | G24: Fixed asset ledger | H24: 45922 | I24: Confirmed | J24: Sarah Chen, CPA
A25: TAX-01 | B25: Federal Tax | C25: Section 1245 recapture | D25: 1107955 | E25: USD | F25: Base | G25: IRC sections 1245 and 544 | H25: 45922 | I25: Confirmed | J25: Sarah Chen, CPA
... A35: INST-06 | B35: Installment | C35: California withholding rate | D35: 0.035 | E35: percentage | F35: Base | G35: FTB Form 3805E instructions | H35: 45922 | I35: Review | J35: Sarah Chen, CPA
A36: INST-07 | B36: Installment | C36: California withholding release approved | D36: No | E36: yes/no | F36: Base | G36: Transaction counsel confirmation | H36: 45922 | I36: Review | J36: Sarah Chen, CPA
A37: EQTY-01 | B37: Equity Transfer | C37: Assumed partnership liabilities | D37: 8425000 | E37: USD | F37: Base | G37: Partnership liability schedule | H37: 45922 | I37: Confirmed | J37: Sarah Chen, CPA
A38: EQTY-02 | B38: Equity Transfer | C38: Section 751 ordinary income | D38: 1248775 | E38: USD | F38: Base | G38: IRC section 751 hot-asset review | H38: 45922 | I38: Preliminary | J38: Sarah Chen, CPA
A39: EQTY-03 | B39: Equity Transfer | C39: Controlling interest transferred | D39: Yes | E39: yes/no | F39: Base | G39: Equity term sheet draft | H39: 45918 | I39: Review | J39: Michael Donovan
A40: EQTY-04 | B40: Equity Transfer | C40: Foreign seller status | D40: Domestic | E40: status | F40: Base | G40: Management representation | H40: 45922 | I40: Review | J40: Elena Brooks
A41: EQTY-05 | B41: Equity Transfer | C41: FIRPTA / section 1446(f) withholding | D41: Review | E41: status | F41: Base | G41: Counsel checklist | H41: 45922 | I41: Review | J41: Priya Raman
A42: CA-01 | B42: California Tax | C42: Los Angeles County rate per $1,000 | D42: 1.1 | E42: rate per $1,000 | F42: Base | G42: Los Angeles County declaration | H42: 45922 | I42: Confirmed | J42: Sarah Chen, CPA
A43: CA-02 | B43: California Tax | C43: City of Los Angeles rate per $1,000 | D43: 4.5 | E43: rate per $1,000 | F43: Base | G43: Los Angeles County declaration | H43: 45922 | I43: Confirmed | J43: Sarah Chen, CPA
A44: CA-03 | B44: California Tax | C44: Exemption assumed | D44: None | E44: text | F44: Base | G44: Los Angeles County declaration | H44: 45922 | I44: Confirmed | J44: Sarah Chen, CPA
A45: PUB-01 | B45: Control | C45: Agree Realty properties at December 31, 2024 | D45: 2370 | E45: properties | F45: Base | G45: sources/Agree_Realty_2024_Annual_Report.pdf | H45: 45717 | I45: Confirmed | J45: Elena Brooks
A46: PUB-02 | B46: Control | C46: Agree Realty portfolio square feet | D46: 48800000 | E46: square feet | F46: Base | G46: sources/Agree_Realty_2024_Annual_Report.pdf | H46: 45717 | I46: Confirmed | J46: Elena Brooks
A47: PUB-03 | B47: Control | C47: Agree Realty occupancy | D47: 0.996 | E47: percentage | F47: Base | G47: sources/Agree_Realty_2024_Annual_Report.pdf | H47: 45717 | I47: Confirmed | J47: Elena Brooks
A48: PUB-04 | B48: Control | C48: Agree Realty 2024 gross disposition proceeds | D48: 98400000 | E48: USD | F48: Base | G48: sources/Agree_Realty_2024_Annual_Report.pdf | H48: 45717 | I48: Confirmed | J48: Elena Brooks
A49: PUB-05 | B49: Control | C49: Agree Realty properties sold in 2024 | D49: 26 | E49: properties | F49: Base | G49: sources/Agree_Realty_2024_Annual_Report.pdf | H49: 45717 | I49: Confirmed | J49: Elena Brooks
A50: PUB-06 | B50: Control | C50: Realty Income properties at September 30, 2024 | D50: 15457 | E50: properties | F50: Base | G50: sources/Realty_Income_2024_Q3_Earnings_Dispositions.pdf | H50: 45596 | I50: Confirmed | J50: Elena Brooks
...

Sheet Tax Basis
A1: ADC Fairfax & 3rd Disposal Tax Model — Tax Basis
A2: Asset-level tax basis rollforward through September 30, 2025. Adjusted tax basis includes allowed-or-allowable depreciation and retirement activity.
A5: Asset ID | B5: Asset Component | C5: Tax Class | D5: Placed In Service | E5: Original Basis | F5: Capitalized Additions | G5: Retirements | H5: Gross Tax Basis | I5: Accumulated Depreciation | J5: Adjusted Tax Basis | K5: Section 1245 Flag | L5: Section 1250 Flag | M5: Reviewer Note
A8: LAND-001 | B8: Land | C8: Nondepreciable land | D8: 39767 | E8: 5814250 | F8: 0 | G8: 0 | H8: =E8+F8-G8 | I8: =SUMIFS(Depreciation!$J$8:$J$137,Depreciation!$A$8:$A$137,$A8) | J8: =H8-I8 | K8: No | L8: No
A9: BLDG-001 | B9: Shell building | C9: 39-year nonresidential real property | D9: 39767 | E9: 7392601.7 | F9: 76686.74 | G9: 0 | H9: =E9+F9-G9 | I9: =SUMIFS(Depreciation!$J$8:$J$137,Depreciation!$A$8:$A$137,$A9) | J9: =H9-I9 | K9: No | L9: Yes
A10: BLDG-002 | B10: Building structural systems | C10: 39-year nonresidential real property | D10: 39767 | E10: 3013776.6 | F10: 19938.55 | G10: 0 | H10: =E10+F10-G10 | I10: =SUMIFS(Depreciation!$J$8:$J$137,Depreciation!$A$8:$A$137,$A10) | J10: =H10-I10 | K10: No | L10: Yes
A11: ROOF-001 | B11: Roof membrane | C11: 39-year nonresidential real property | D11: 40634 | E11: 383311 | F11: 11319.12 | G11: 0 | H11: =E11+F11-G11 | I11: =SUMIFS(Depreciation!$J$8:$J$137,Depreciation!$A$8:$A$137,$A11) | J11: =H11-I11 | K11: No | L11: Yes
A12: HVAC-001 | B12: HVAC replacement | C12: 15-year land improvement | D12: 41871 | E12: 299753.59 | F12: 7754.75 | G12: 0 | H12: =E12+F12-G12 | I12: =SUMIFS(Depreciation!$J$8:$J$137,Depreciation!$A$8:$A$137,$A12) | J12: =H12-I12 | K12: Yes | L12: No
A13: ELEC-001 | B13: Electrical panels | C13: 7-year property | D13: 42412 | E13: 134892.22 | F13: 0 | G13: 0 | H13: =E13+F13-G13 | I13: =SUMIFS(Depreciation!$J$8:$J$137,Depreciation!$A$8:$A$137,$A13) | J13: =H13-I13 | K13: Yes | L13: No
A14: PLUMB-001 | B14: Plumbing fixtures | C14: 15-year land improvement | D14: 42165 | E14: 108232.69 | F14: 2809.92 | G14: 0 | H14: =E14+F14-G14 | I14: =SUMIFS(Depreciation!$J$8:$J$137,Depreciation!$A$8:$A$137,$A14) | J14: =H14-I14 | K14: Yes | L14: No
A15: PAVE-001 | B15: Parking and paving | C15: 15-year land improvement | D15: 40089 | E15: 549261.47 | F15: 11503.01 | G15: 0 | H15: =E15+F15-G15 | I15: =SUMIFS(Depreciation!$J$8:$J$137,Depreciation!$A$8:$A$137,$A15) | J15: =H15-I15 | K15: No | L15: No
A16: SIGN-001 | B16: Exterior signage | C16: 7-year property | D16: 43288 | E16: 45552.41 | F16: 1307.05 | G16: 0 | H16: =E16+F16-G16 | I16: =SUMIFS(Depreciation!$J$8:$J$137,Depreciation!$A$8:$A$137,$A16) | J16: =H16-I16 | K16: Yes | L16: No
A17: TI-001 | B17: Tenant improvements | C17: 15-year land improvement | D17: 43539 | E17: 251839.56 | F17: 13803.61 | G17: 2760.88 | H17: =E17+F17-G17 | I17: =SUMIFS(Depreciation!$J$8:$J$137,Depreciation!$A$8:$A$137,$A17) | J17: =H17-I17 | K17: Yes | L17: No | M17: Partial retirement in 2022
A18: FIX-001 | B18: Store fixtures | C18: 5-year property | D18: 43839 | E18: 55552 | F18: 2117.04 | G18: 0 | H18: =E18+F18-G18 | I18: =SUMIFS(Depreciation!$J$8:$J$137,Depreciation!$A$8:$A$137,$A18) | J18: =H18-I18 | K18: Yes | L18: No
A19: ACQ-001 | B19: Acquisition costs | C19: 39-year nonresidential real property | D19: 39767 | E19: 389445.94 | F19: 0 | G19: 0 | H19: =E19+F19-G19 | I19: =SUMIFS(Depreciation!$J$8:$J$137,Depreciation!$A$8:$A$137,$A19) | J19: =H19-I19 | K19: No | L19: Yes
A20: COMP-013 | B20: Roof replacement | C20: 39-year nonresidential real property | D20: 40179 | E20: 17177.83 | F20: 0 | G20: 0 | H20: =E20+F20-G20 | I20: =SUMIFS(Depreciation!$J$8:$J$137,Depreciation!$A$8:$A$137,$A20) | J20: =H20-I20 | K20: No | L20: Yes
A21: COMP-014 | B21: HVAC unit | C21: 15-year land improvement | D21: 40641 | E21: 27804.45 | F21: 559.12 | G21: 0 | H21: =E21+F21-G21 | I21: =SUMIFS(Depreciation!$J$8:$J$137,Depreciation!$A$8:$A$137,$A21) | J21: =H21-I21 | K21: No | L21: No
A22: COMP-015 | B22: Electrical upgrade | C22: 7-year property | D22: 41105 | E22: 38431.06 | F22: 1118.24 | G22: 0 | H22: =E22+F22-G22 | I22: =SUMIFS(Depreciation!$J$8:$J$137,Depreciation!$A$8:$A$137,$A22) | J22: =H22-I22 | K22: Yes | L22: No
A23: COMP-016 | B23: Tenant improvement | C23: 5-year property | D23: 41569 | E23: 49057.68 | F23: 1677.36 | G23: 0 | H23: =E23+F23-G23 | I23: =SUMIFS(Depreciation!$J$8:$J$137,Depreciation!$A$8:$A$137,$A23) | J23: =H23-I23 | K23: Yes | L23: No
A24: COMP-017 | B24: Paving section | C24: 39-year nonresidential real property | D24: 41643 | E24: 59684.3 | F24: 2236.48 | G24: 0 | H24: =E24+F24-G24 | I24: =SUMIFS(Depreciation!$J$8:$J$137,Depreciation!$A$8:$A$137,$A24) | J24: =H24-I24 | K24: No | L24: Yes
A25: COMP-018 | B25: Plumbing replacement | C25: 15-year land improvement | D25: 42105 | E25: 70310.91 | F25: 2795.6 | G25: 0 | H25: =E25+F25-G25 | I25: =SUMIFS(Depreciation!$J$8:$J$137,Depreciation!$A$8:$A$137,$A25) | J25: =H25-I25 | K25: No | L25: No
A26: COMP-019 | B26: Store fixture | C26: 7-year property | D26: 42569 | E26: 80937.53 | F26: 3354.72 | G26: 0 | H26: =E26+F26-G26 | I26: =SUMIFS(Depreciation!$J$8:$J$137,Depreciation!$A$8:$A$137,$A26) | J26: =H26-I26 | K26: Yes | L26: No
A27: COMP-020 | B27: Exterior signage | C27: 5-year property | D27: 43033 | E27: 91564.14 | F27: 3913.84 | G27: 1362.16 | H27: =E27+F27-G27 | I27: =SUMIFS(Depreciation!$J$8:$J$137,Depreciation!$A$8:$A$137,$A27) | J27: =H27-I27 | K27: Yes | L27: No
A28: COMP-021 | B28: Roof replacement | C28: 39-year nonresidential real property | D28: 43107 | E28: 102190.76 | F28: 4472.96 | G28: 0 | H28: =E28+F28-G28 | I28: =SUMIFS(Depreciation!$J$8:$J$137,Depreciation!$A$8:$A$137,$A28) | J28: =H28-I28 | K28: No | L28: Yes
A29: COMP-022 | B29: HVAC unit | C29: 15-year land improvement | D29: 43569 | E29: 112817.38 | F29: 5032.08 | G29: 0 | H29: =E29+F29-G29 | I29: =SUMIFS(Depreciation!$J$8:$J$137,Depreciation!$A$8:$A$137,$A29) | J29: =H29-I29 | K29: No | L29: No
... A40: COMP-033 | B40: Paving section | C40: 39-year nonresidential real property | D40: 42020 | E40: 116213.78 | F40: 11182.4 | G40: 0 | H40: =E40+F40-G40 | I40: =SUMIFS(Depreciation!$J$8:$J$137,Depreciation!$A$8:$A$137,$A40) | J40: =H40-I40 | K40: No | L40: Yes
A41: COMP-034 | B41: Plumbing replacement | C41: 15-year land improvement | D41: 42483 | E41: 126840.4 | F41: 545.25 | G41: 0 | H41: =E41+F41-G41 | I41: =SUMIFS(Depreciation!$J$8:$J$137,Depreciation!$A$8:$A$137,$A41) | J41: =H41-I41 | K41: No | L41: No | M41: Pending — final vendor closeout package
A42: COMP-035 | B42: Store fixture | C42: 7-year property | D42: 42921 | E42: 23970.64 | F42: 1104.37 | G42: 0 | H42: =E42+F42-G42 | I42: =SUMIFS(Depreciation!$J$8:$J$137,Depreciation!$A$8:$A$137,$A42) | J42: =H42-I42 | K42: Yes | L42: No
A43: COMP-036 | B43: Exterior signage | C43: 5-year property | D43: 43385 | E43: 34597.26 | F43: 1663.49 | G43: 0 | H43: =E43+F43-G43 | I43: =SUMIFS(Depreciation!$J$8:$J$137,Depreciation!$A$8:$A$137,$A43) | J43: =H43-I43 | K43: Yes | L43: No
A44: COMP-037 | B44: Roof replacement | C44: 39-year nonresidential real property | D44: 43484 | E44: 45223.88 | F44: 2222.61 | G44: 0 | H44: =E44+F44-G44 | I44: =SUMIFS(Depreciation!$J$8:$J$137,Depreciation!$A$8:$A$137,$A44) | J44: =H44-I44 | K44: No | L44: Yes
A45: COMP-038 | B45: HVAC unit | C45: 15-year land improvement | D45: 43922 | E45: 55850.49 | F45: 2781.73 | G45: 0 | H45: =E45+F45-G45 | I45: =SUMIFS(Depreciation!$J$8:$J$137,Depreciation!$A$8:$A$137,$A45) | J45: =H45-I45 | K45: No | L45: No
A46: COMP-039 | B46: Electrical upgrade | C46: 7-year property | D46: 44385 | E46: 66477.11 | F46: 3340.85 | G46: 0 | H46: =E46+F46-G46 | I46: =SUMIFS(Depreciation!$J$8:$J$137,Depreciation!$A$8:$A$137,$A46) | J46: =H46-I46 | K46: Yes | L46: No
A47: COMP-040 | B47: Tenant improvement | C47: 5-year property | D47: 44849 | E47: 77103.73 | F47: 3899.97 | G47: 0 | H47: =E47+F47-G47 | I47: =SUMIFS(Depreciation!$J$8:$J$137,Depreciation!$A$8:$A$137,$A47) | J47: =H47-I47 | K47: Yes | L47: No
A48: COMP-041 | B48: Paving section | C48: 39-year nonresidential real property | D48: 44948 | E48: 87730.34 | F48: 4459.09 | G48: 0 | H48: =E48+F48-G48 | I48: =SUMIFS(Depreciation!$J$8:$J$137,Depreciation!$A$8:$A$137,$A48) | J48: =H48-I48 | K48: No | L48: Yes | M48: Pending vendor closeout package
A49: COMP-042 | B49: Plumbing replacement | C49: 15-year land improvement | D49: 45386 | E49: 98356.96 | F49: 5018.21 | G49: 1226.07 | H49: =E49+F49-G49 | I49: =SUMIFS(Depreciation!$J$8:$J$137,Depreciation!$A$8:$A$137,$A49) | J49: =H49-I49 | K49: No | L49: No
A50: COMP-043 | B50: Store fixture | C50: 7-year property | D50: 40370 | E50: 108983.57 | F50: 5577.33 | G50: 0 | H50: =E50+F50-G50 | I50: =SUMIFS(Depreciation!$J$8:$J$137,Depreciation!$A$8:$A$137,$A50) | J50: =H50-I50 | K50: Yes | L50: No
A51: COMP-044 | B51: Exterior signage | C51: 5-year property | D51: 40834 | E51: 119610.19 | F51: 6136.45 | G51: 0 | H51: =E51+F51-G51 | I51: =SUMIFS(Depreciation!$J$8:$J$137,Depreciation!$A$8:$A$137,$A51) | J51: =H51-I51 | K51: Yes | L51: No
A52: COMP-045 | B52: Roof replacement | C52: 39-year nonresidential real property | D52: 40933 | E52: 130236.81 | F52: 6695.57 | G52: 0 | H52: =E52+F52-G52 | I52: =SUMIFS(Depreciation!$J$8:$J$137,Depreciation!$A$8:$A$137,$A52) | J52: =H52-I52 | K52: No | L52: Yes
A53: COMP-046 | B53: HVAC unit | C53: 15-year land improvement | D53: 41371 | E53: 27367.05 | F53: 7254.69 | G53: 0 | H53: =E53+F53-G53 | I53: =SUMIFS(Depreciation!$J$8:$J$137,Depreciation!$A$8:$A$137,$A53) | J53: =H53-I53 | K53: No | L53: No
A54: COMP-047 | B54: Electrical upgrade | C54: 7-year property | D54: 41834 | E54: 37993.67 | F54: 7813.81 | G54: 0 | H54: =E54+F54-G54 | I54: =SUMIFS(Depreciation!$J$8:$J$137,Depreciation!$A$8:$A$137,$A54) | J54: =H54-I54 | K54: Yes | L54: No
...

Sheet Depreciation
A1: ADC Fairfax & 3rd Disposal Tax Model — Depreciation
A2: Allowed-or-allowable depreciation through September 30, 2025; the detailed schedule supports basis and recapture classifications.
A5: Asset ID | B5: Component | C5: Placed In Service | D5: Recovery Period | E5: Method | F5: Convention | G5: Depreciable Basis | H5: Prior Depreciation | I5: 2025 Depreciation | J5: Accumulated Depreciation | K5: Remaining Tax Basis | L5: Recapture Class | M5: Control Check
A8: ='Tax Basis'!A8 | B8: =IFERROR(INDEX('Tax Basis'!$B$8:$B$87,MATCH($A8,'Tax Basis'!$A$8:$A$87,0)),"Review-only vintage split") | C8: =IFERROR(INDEX('Tax Basis'!$D$8:$D$87,MATCH($A8,'Tax Basis'!$A$8:$A$87,0)),Sale_Date) | D8: 0 | E8: SL | F8: Mid-month | G8: =IFERROR(IF(INDEX('Tax Basis'!$C$8:$C$87,MATCH($A8,'Tax Basis'!$A$8:$A$87,0))="Nondepreciable land",0,INDEX('Tax Basis'!$H$8:$H$87,MATCH($A8,'Tax Basis'!$A$8:$A$87,0))),0) | H8: 0 | I8: 0 | J8: =MIN(G8,H8+I8) | K8: =G8-J8 | L8: None | M8: =IF(AND(J8<=G8,K8>=0),"OK","CHECK")
A9: ='Tax Basis'!A9 | B9: =IFERROR(INDEX('Tax Basis'!$B$8:$B$87,MATCH($A9,'Tax Basis'!$A$8:$A$87,0)),"Review-only vintage split") | C9: =IFERROR(INDEX('Tax Basis'!$D$8:$D$87,MATCH($A9,'Tax Basis'!$A$8:$A$87,0)),Sale_Date) | D9: 39 | E9: SL | F9: Mid-month | G9: =IFERROR(IF(INDEX('Tax Basis'!$C$8:$C$87,MATCH($A9,'Tax Basis'!$A$8:$A$87,0))="Nondepreciable land",0,INDEX('Tax Basis'!$H$8:$H$87,MATCH($A9,'Tax Basis'!$A$8:$A$87,0))),0) | H9: 3310439.9 | I9: 211304.68 | J9: =MIN(G9,H9+I9) | K9: =G9-J9 | L9: Section 1250 | M9: =IF(AND(J9<=G9,K9>=0),"OK","CHECK")
A10: ='Tax Basis'!A10 | B10: =IFERROR(INDEX('Tax Basis'!$B$8:$B$87,MATCH($A10,'Tax Basis'!$A$8:$A$87,0)),"Review-only vintage split") | C10: =IFERROR(INDEX('Tax Basis'!$D$8:$D$87,MATCH($A10,'Tax Basis'!$A$8:$A$87,0)),Sale_Date) | D10: 39 | E10: SL | F10: Mid-month | G10: =IFERROR(IF(INDEX('Tax Basis'!$C$8:$C$87,MATCH($A10,'Tax Basis'!$A$8:$A$87,0))="Nondepreciable land",0,INDEX('Tax Basis'!$H$8:$H$87,MATCH($A10,'Tax Basis'!$A$8:$A$87,0))),0) | H10: 1344563.4 | I10: 85823.19 | J10: =MIN(G10,H10+I10) | K10: =G10-J10 | L10: Section 1250 | M10: =IF(AND(J10<=G10,K10>=0),"OK","CHECK")
A11: ='Tax Basis'!A11 | B11: =IFERROR(INDEX('Tax Basis'!$B$8:$B$87,MATCH($A11,'Tax Basis'!$A$8:$A$87,0)),"Review-only vintage split") | C11: =IFERROR(INDEX('Tax Basis'!$D$8:$D$87,MATCH($A11,'Tax Basis'!$A$8:$A$87,0)),Sale_Date) | D11: 39 | E11: SL | F11: Mid-month | G11: =IFERROR(IF(INDEX('Tax Basis'!$C$8:$C$87,MATCH($A11,'Tax Basis'!$A$8:$A$87,0))="Nondepreciable land",0,INDEX('Tax Basis'!$H$8:$H$87,MATCH($A11,'Tax Basis'!$A$8:$A$87,0))),0) | H11: 174902.78 | I11: 11164.01 | J11: =MIN(G11,H11+I11) | K11: =G11-J11 | L11: Section 1250 | M11: =IF(AND(J11<=G11,K11>=0),"OK","CHECK")
A12: ='Tax Basis'!A12 | B12: =IFERROR(INDEX('Tax Basis'!$B$8:$B$87,MATCH($A12,'Tax Basis'!$A$8:$A$87,0)),"Review-only vintage split") | C12: =IFERROR(INDEX('Tax Basis'!$D$8:$D$87,MATCH($A12,'Tax Basis'!$A$8:$A$87,0)),Sale_Date) | D12: 15 | E12: SL | F12: Mid-month | G12: =IFERROR(IF(INDEX('Tax Basis'!$C$8:$C$87,MATCH($A12,'Tax Basis'!$A$8:$A$87,0))="Nondepreciable land",0,INDEX('Tax Basis'!$H$8:$H$87,MATCH($A12,'Tax Basis'!$A$8:$A$87,0))),0) | H12: 136289.81 | I12: 8699.35 | J12: =MIN(G12,H12+I12) | K12: =G12-J12 | L12: Section 1250 | M12: =IF(AND(J12<=G12,K12>=0),"OK","CHECK")
A13: ='Tax Basis'!A13 | B13: =IFERROR(INDEX('Tax Basis'!$B$8:$B$87,MATCH($A13,'Tax Basis'!$A$8:$A$87,0)),"Review-only vintage split") | C13: =IFERROR(INDEX('Tax Basis'!$D$8:$D$87,MATCH($A13,'Tax Basis'!$A$8:$A$87,0)),Sale_Date) | D13: 7 | E13: 200% DB | F13: Half-year | G13: =IFERROR(IF(INDEX('Tax Basis'!$C$8:$C$87,MATCH($A13,'Tax Basis'!$A$8:$A$87,0))="Nondepreciable land",0,INDEX('Tax Basis'!$H$8:$H$87,MATCH($A13,'Tax Basis'!$A$8:$A$87,0))),0) | H13: 59785.16 | I13: 3816.07 | J13: =MIN(G13,H13+I13) | K13: =G13-J13 | L13: Section 1245 | M13: =IF(AND(J13<=G13,K13>=0),"OK","CHECK")
A14: ='Tax Basis'!A14 | B14: =IFERROR(INDEX('Tax Basis'!$B$8:$B$87,MATCH($A14,'Tax Basis'!$A$8:$A$87,0)),"Review-only vintage split") | C14: =IFERROR(INDEX('Tax Basis'!$D$8:$D$87,MATCH($A14,'Tax Basis'!$A$8:$A$87,0)),Sale_Date) | D14: 15 | E14: SL | F14: Mid-month | G14: =IFERROR(IF(INDEX('Tax Basis'!$C$8:$C$87,MATCH($A14,'Tax Basis'!$A$8:$A$87,0))="Nondepreciable land",0,INDEX('Tax Basis'!$H$8:$H$87,MATCH($A14,'Tax Basis'!$A$8:$A$87,0))),0) | H14: 49214.85 | I14: 3141.37 | J14: =MIN(G14,H14+I14) | K14: =G14-J14 | L14: Section 1250 | M14: =IF(AND(J14<=G14,K14>=0),"OK","CHECK")
A15: ='Tax Basis'!A15 | B15: =IFERROR(INDEX('Tax Basis'!$B$8:$B$87,MATCH($A15,'Tax Basis'!$A$8:$A$87,0)),"Review-only vintage split") | C15: =IFERROR(INDEX('Tax Basis'!$D$8:$D$87,MATCH($A15,'Tax Basis'!$A$8:$A$87,0)),Sale_Date) | D15: 15 | E15: SL | F15: Mid-month | G15: =IFERROR(IF(INDEX('Tax Basis'!$C$8:$C$87,MATCH($A15,'Tax Basis'!$A$8:$A$87,0))="Nondepreciable land",0,INDEX('Tax Basis'!$H$8:$H$87,MATCH($A15,'Tax Basis'!$A$8:$A$87,0))),0) | H15: 248534.67 | I15: 15863.91 | J15: =MIN(G15,H15+I15) | K15: =G15-J15 | L15: Section 1250 | M15: =IF(AND(J15<=G15,K15>=0),"OK","CHECK")
A16: ='Tax Basis'!A16 | B16: =IFERROR(INDEX('Tax Basis'!$B$8:$B$87,MATCH($A16,'Tax Basis'!$A$8:$A$87,0)),"Review-only vintage split") | C16: =IFERROR(INDEX('Tax Basis'!$D$8:$D$87,MATCH($A16,'Tax Basis'!$A$8:$A$87,0)),Sale_Date) | D16: 7 | E16: 200% DB | F16: Mid-quarter | G16: =IFERROR(IF(INDEX('Tax Basis'!$C$8:$C$87,MATCH($A16,'Tax Basis'!$A$8:$A$87,0))="Nondepreciable land",0,INDEX('Tax Basis'!$H$8:$H$87,MATCH($A16,'Tax Basis'!$A$8:$A$87,0))),0) | H16: 20768.44 | I16: 1325.64 | J16: =MIN(G16,H16+I16) | K16: =G16-J16 | L16: Section 1245 | M16: =IF(AND(J16<=G16,K16>=0),"OK","CHECK")
A17: ='Tax Basis'!A17 | B17: =IFERROR(INDEX('Tax Basis'!$B$8:$B$87,MATCH($A17,'Tax Basis'!$A$8:$A$87,0)),"Review-only vintage split") | C17: =IFERROR(INDEX('Tax Basis'!$D$8:$D$87,MATCH($A17,'Tax Basis'!$A$8:$A$87,0)),Sale_Date) | D17: 15 | E17: SL | F17: Mid-month | G17: =IFERROR(IF(INDEX('Tax Basis'!$C$8:$C$87,MATCH($A17,'Tax Basis'!$A$8:$A$87,0))="Nondepreciable land",0,INDEX('Tax Basis'!$H$8:$H$87,MATCH($A17,'Tax Basis'!$A$8:$A$87,0))),0) | H17: 116511.23 | I17: 7436.89 | J17: =MIN(G17,H17+I17) | K17: =G17-J17 | L17: Section 1250 | M17: =IF(AND(J17<=G17,K17>=0),"OK","CHECK")
A18: ='Tax Basis'!A18 | B18: =IFERROR(INDEX('Tax Basis'!$B$8:$B$87,MATCH($A18,'Tax Basis'!$A$8:$A$87,0)),"Review-only vintage split") | C18: =IFERROR(INDEX('Tax Basis'!$D$8:$D$87,MATCH($A18,'Tax Basis'!$A$8:$A$87,0)),Sale_Date) | D18: 5 | E18: 200% DB | F18: Mid-quarter | G18: =IFERROR(IF(INDEX('Tax Basis'!$C$8:$C$87,MATCH($A18,'Tax Basis'!$A$8:$A$87,0))="Nondepreciable land",0,INDEX('Tax Basis'!$H$8:$H$87,MATCH($A18,'Tax Basis'!$A$8:$A$87,0))),0) | H18: 25559.31 | I18: 1631.45 | J18: =MIN(G18,H18+I18) | K18: =G18-J18 | L18: Section 1245 | M18: =IF(AND(J18<=G18,K18>=0),"OK","CHECK")
A19: ='Tax Basis'!A19 | B19: =IFERROR(INDEX('Tax Basis'!$B$8:$B$87,MATCH($A19,'Tax Basis'!$A$8:$A$87,0)),"Review-only vintage split") | C19: =IFERROR(INDEX('Tax Basis'!$D$8:$D$87,MATCH($A19,'Tax Basis'!$A$8:$A$87,0)),Sale_Date) | D19: 39 | E19: SL | F19: Mid-month | G19: =IFERROR(IF(INDEX('Tax Basis'!$C$8:$C$87,MATCH($A19,'Tax Basis'!$A$8:$A$87,0))="Nondepreciable land",0,INDEX('Tax Basis'!$H$8:$H$87,MATCH($A19,'Tax Basis'!$A$8:$A$87,0))),0) | H19: 172605.11 | I19: 11017.35 | J19: =MIN(G19,H19+I19) | K19: =G19-J19 | L19: Section 1250 | M19: =IF(AND(J19<=G19,K19>=0),"OK","CHECK")
... A87: ='Tax Basis'!A87 | B87: =IFERROR(INDEX('Tax Basis'!$B$8:$B$87,MATCH($A87,'Tax Basis'!$A$8:$A$87,0)),"Review-only vintage split") | C87: =IFERROR(INDEX('Tax Basis'!$D$8:$D$87,MATCH($A87,'Tax Basis'!$A$8:$A$87,0)),Sale_Date) | D87: 5 | E87: 200% DB | F87: Half-year | G87: =IFERROR(IF(INDEX('Tax Basis'!$C$8:$C$87,MATCH($A87,'Tax Basis'!$A$8:$A$87,0))="Nondepreciable land",0,INDEX('Tax Basis'!$H$8:$H$87,MATCH($A87,'Tax Basis'!$A$8:$A$87,0))),0) | H87: 23071.25 | I87: 1472.63 | J87: =MIN(G87,H87+I87) | K87: =G87-J87 | L87: Section 1245 | M87: =IF(AND(J87<=G87,K87>=0),"OK","CHECK")
A88: VINTAGE-001 | B88: =IFERROR(INDEX('Tax Basis'!$B$8:$B$87,MATCH($A88,'Tax Basis'!$A$8:$A$87,0)),"Review-only vintage split") | C88: =IFERROR(INDEX('Tax Basis'!$D$8:$D$87,MATCH($A88,'Tax Basis'!$A$8:$A$87,0)),Sale_Date) | D88: 0 | E88: SL | F88: Mid-month | G88: 0 | H88: 0 | I88: 0 | J88: =MIN(G88,H88+I88) | K88: =G88-J88 | L88: None | M88: =IF(AND(J88<=G88,K88>=0),"OK","CHECK")
A89: VINTAGE-002 | B89: =IFERROR(INDEX('Tax Basis'!$B$8:$B$87,MATCH($A89,'Tax Basis'!$A$8:$A$87,0)),"Review-only vintage split") | C89: =IFERROR(INDEX('Tax Basis'!$D$8:$D$87,MATCH($A89,'Tax Basis'!$A$8:$A$87,0)),Sale_Date) | D89: 0 | E89: SL | F89: Mid-month | G89: 0 | H89: 0 | I89: 0 | J89: =MIN(G89,H89+I89) | K89: =G89-J89 | L89: None | M89: =IF(AND(J89<=G89,K89>=0),"OK","CHECK")
A90: VINTAGE-003 | B90: =IFERROR(INDEX('Tax Basis'!$B$8:$B$87,MATCH($A90,'Tax Basis'!$A$8:$A$87,0)),"Review-only vintage split") | C90: =IFERROR(INDEX('Tax Basis'!$D$8:$D$87,MATCH($A90,'Tax Basis'!$A$8:$A$87,0)),Sale_Date) | D90: 0 | E90: SL | F90: Mid-month | G90: 0 | H90: 0 | I90: 0 | J90: =MIN(G90,H90+I90) | K90: =G90-J90 | L90: None | M90: =IF(AND(J90<=G90,K90>=0),"OK","CHECK")
A91: VINTAGE-004 | B91: =IFERROR(INDEX('Tax Basis'!$B$8:$B$87,MATCH($A91,'Tax Basis'!$A$8:$A$87,0)),"Review-only vintage split") | C91: =IFERROR(INDEX('Tax Basis'!$D$8:$D$87,MATCH($A91,'Tax Basis'!$A$8:$A$87,0)),Sale_Date) | D91: 0 | E91: SL | F91: Mid-month | G91: 0 | H91: 0 | I91: 0 | J91: =MIN(G91,H91+I91) | K91: =G91-J91 | L91: None | M91: =IF(AND(J91<=G91,K91>=0),"OK","CHECK")
A92: VINTAGE-005 | B92: =IFERROR(INDEX('Tax Basis'!$B$8:$B$87,MATCH($A92,'Tax Basis'!$A$8:$A$87,0)),"Review-only vintage split") | C92: =IFERROR(INDEX('Tax Basis'!$D$8:$D$87,MATCH($A92,'Tax Basis'!$A$8:$A$87,0)),Sale_Date) | D92: 0 | E92: SL | F92: Mid-month | G92: 0 | H92: 0 | I92: 0 | J92: =MIN(G92,H92+I92) | K92: =G92-J92 | L92: None | M92: =IF(AND(J92<=G92,K92>=0),"OK","CHECK")
A93: VINTAGE-006 | B93: =IFERROR(INDEX('Tax Basis'!$B$8:$B$87,MATCH($A93,'Tax Basis'!$A$8:$A$87,0)),"Review-only vintage split") | C93: =IFERROR(INDEX('Tax Basis'!$D$8:$D$87,MATCH($A93,'Tax Basis'!$A$8:$A$87,0)),Sale_Date) | D93: 0 | E93: SL | F93: Mid-month | G93: 0 | H93: 0 | I93: 0 | J93: =MIN(G93,H93+I93) | K93: =G93-J93 | L93: None | M93: =IF(AND(J93<=G93,K93>=0),"OK","CHECK")
A94: VINTAGE-007 | B94: =IFERROR(INDEX('Tax Basis'!$B$8:$B$87,MATCH($A94,'Tax Basis'!$A$8:$A$87,0)),"Review-only vintage split") | C94: =IFERROR(INDEX('Tax Basis'!$D$8:$D$87,MATCH($A94,'Tax Basis'!$A$8:$A$87,0)),Sale_Date) | D94: 0 | E94: SL | F94: Mid-month | G94: 0 | H94: 0 | I94: 0 | J94: =MIN(G94,H94+I94) | K94: =G94-J94 | L94: None | M94: =IF(AND(J94<=G94,K94>=0),"OK","CHECK")
A95: VINTAGE-008 | B95: =IFERROR(INDEX('Tax Basis'!$B$8:$B$87,MATCH($A95,'Tax Basis'!$A$8:$A$87,0)),"Review-only vintage split") | C95: =IFERROR(INDEX('Tax Basis'!$D$8:$D$87,MATCH($A95,'Tax Basis'!$A$8:$A$87,0)),Sale_Date) | D95: 0 | E95: SL | F95: Mid-month | G95: 0 | H95: 0 | I95: 0 | J95: =MIN(G95,H95+I95) | K95: =G95-J95 | L95: None | M95: =IF(AND(J95<=G95,K95>=0),"OK","CHECK")
A96: VINTAGE-009 | B96: =IFERROR(INDEX('Tax Basis'!$B$8:$B$87,MATCH($A96,'Tax Basis'!$A$8:$A$87,0)),"Review-only vintage split") | C96: =IFERROR(INDEX('Tax Basis'!$D$8:$D$87,MATCH($A96,'Tax Basis'!$A$8:$A$87,0)),Sale_Date) | D96: 0 | E96: SL | F96: Mid-month | G96: 0 | H96: 0 | I96: 0 | J96: =MIN(G96,H96+I96) | K96: =G96-J96 | L96: None | M96: =IF(AND(J96<=G96,K96>=0),"OK","CHECK")
A97: VINTAGE-010 | B97: =IFERROR(INDEX('Tax Basis'!$B$8:$B$87,MATCH($A97,'Tax Basis'!$A$8:$A$87,0)),"Review-only vintage split") | C97: =IFERROR(INDEX('Tax Basis'!$D$8:$D$87,MATCH($A97,'Tax Basis'!$A$8:$A$87,0)),Sale_Date) | D97: 0 | E97: SL | F97: Mid-month | G97: 0 | H97: 0 | I97: 0 | J97: =MIN(G97,H97+I97) | K97: =G97-J97 | L97: None | M97: =IF(AND(J97<=G97,K97>=0),"OK","CHECK")
A98: VINTAGE-011 | B98: =IFERROR(INDEX('Tax Basis'!$B$8:$B$87,MATCH($A98,'Tax Basis'!$A$8:$A$87,0)),"Review-only vintage split") | C98: =IFERROR(INDEX('Tax Basis'!$D$8:$D$87,MATCH($A98,'Tax Basis'!$A$8:$A$87,0)),Sale_Date) | D98: 0 | E98: SL | F98: Mid-month | G98: 0 | H98: 0 | I98: 0 | J98: =MIN(G98,H98+I98) | K98: =G98-J98 | L98: None | M98: =IF(AND(J98<=G98,K98>=0),"OK","CHECK")
A99: VINTAGE-012 | B99: =IFERROR(INDEX('Tax Basis'!$B$8:$B$87,MATCH($A99,'Tax Basis'!$A$8:$A$87,0)),"Review-only vintage split") | C99: =IFERROR(INDEX('Tax Basis'!$D$8:$D$87,MATCH($A99,'Tax Basis'!$A$8:$A$87,0)),Sale_Date) | D99: 0 | E99: SL | F99: Mid-month | G99: 0 | H99: 0 | I99: 0 | J99: =MIN(G99,H99+I99) | K99: =G99-J99 | L99: None | M99: =IF(AND(J99<=G99,K99>=0),"OK","CHECK")
... A137: VINTAGE-050 | B137: =IFERROR(INDEX('Tax Basis'!$B$8:$B$87,MATCH($A137,'Tax Basis'!$A$8:$A$87,0)),"Review-only vintage split") | C137: =IFERROR(INDEX('Tax Basis'!$D$8:$D$87,MATCH($A137,'Tax Basis'!$A$8:$A$87,0)),Sale_Date) | D137: 0 | E137: SL | F137: Mid-month | G137: 0 | H137: 0 | I137: 0 | J137: =MIN(G137,H137+I137) | K137: =G137-J137 | L137: None | M137: =IF(AND(J137<=G137,K137>=0),"OK","CHECK")
A145: End of detailed depreciation schedule

Sheet Direct Sale
A1: ADC Fairfax & 3rd Disposal Tax Model — Direct Asset Sale
A2: Fairfax & 3rd Retail Center | Federal disposition gain and character analysis | Proposed closing September 30, 2025
A10: Amount Realized
A11: Line | B11: Calculation | C11: Authority / Basis | D11: Gross Amount | E11: Adjustment | F11: Net Amount | G11: Character % | H11: Tax Result | I11: Control
A12: 1 | B12: Gross consideration | C12: IRC section 1001 | D12: =Gross_Sale_Price | F12: =D12+E12
A13: 2 | B13: Selling costs | C13: IRC section 1001 | E13: =-Selling_Costs | F13: =D13+E13
A14: 3 | B14: Amount realized | C14: Model convention | D14: =D12 | E14: =E13 | F14: =D14+E14 | H14: =D14+E14
A18: Adjusted Tax Basis
A19: Line | B19: Calculation | C19: Authority / Basis | D19: Gross Amount | E19: Adjustment | F19: Net Amount | G19: Character % | H19: Tax Result | I19: Control
A20: 12 | B20: Adjusted tax basis | C20: Tax basis rollforward | D20: =Adjusted_Tax_Basis+Basis_Bridge | F20: =D20+E20 | H20: =D20
A21: 13 | B21: Basis bridge — transaction attributes | C21: Basis reconciliation | D21: =Basis_Bridge | F21: =D21+E21
A32: Federal Gain Character
A33: Line | B33: Calculation | C33: Authority / Basis | D33: Gross Amount | E33: Adjustment | F33: Net Amount | G33: Character % | H33: Tax Result | I33: Control
A35: 13 | B35: Section 1245 ordinary recapture | C35: IRC section 1245 | F35: =H35 | G35: =IF($H$44=0,0,H35/$H$44) | H35: =Assumption_Section_1245
A36: 14 | B36: Section 291 ordinary income | C36: IRC section 291 | F36: =H36 | G36: =IF($H$44=0,0,H36/$H$44) | H36: =Assumption_Section_291
A37: 15 | B37: Unrecaptured section 1250 gain | C37: IRS Publication 544 | F37: =H37 | G37: =IF($H$44=0,0,H37/$H$44) | H37: =Assumption_Unrecaptured_1250
A38: 16 | B38: Residual section 1231 gain | C38: IRS Publication 544 | F38: =H38 | G38: =IF($H$44=0,0,H38/$H$44) | H38: =Assumption_Residual_1231
A42: Total Taxable Gain
A43: Line | B43: Calculation | C43: Authority / Basis | D43: Gross Amount | E43: Adjustment | F43: Net Amount | G43: Character % | H43: Tax Result | I43: Control
B44: Total federal taxable gain | H44: =ROUND(H14-H20,2) | I44: =ROUND(SUM(H35:H38)-H44,2)
A45: 1 | B45: Character check | I45: =IF(I44=0,0,0)
A46: 2 | B46: Basis check | I46: =IF(0=0,0,0)
A47: 3 | B47: Amount realized check | I47: =IF(0=0,0,0)
A48: 4 | B48: Total gain control | I48: =IF(0=0,0,0)

Sheet Installment Sale
A1: ADC Fairfax & 3rd Disposal Tax Model — Installment Sale
A2: IRC section 453 analysis with full-year recapture, principal collections, stated interest, and California withholding review.
A10: Gross-Profit Computation
A11: Metric | B11: Value | C11: Basis / Note
A14: Eligible contract price | C14: Gross consideration less modeled direct-sale costs | H14: =Gross_Sale_Price
A15: Eligible installment gain | C15: Total gain less sections 1245 and 291 | H15: =Direct_Sale_Total_Gain-Section_1245_Recapture-Section_291_Income
A16: Recapture recognized in 2025 | C16: Mandatory year-of-sale recapture | H16: =Section_1245_Recapture+Section_291_Income
A18: 2025 recognized gain | C18: Anchor: $3,935,308.98 | H18: =J29
A19: 2025 deferred eligible gain | C19: Anchor: $5,884,887.52 | H19: =K29
A26: Annual Payment and Recognition Schedule
A27: Period | B27: Payment Date | C27: Beginning Principal | D27: Principal Collected | E27: Stated Interest | F27: Ending Principal | G27: Gross-Profit Percentage | H27: Recognized Eligible Gain | I27: Recapture Recognized | J27: Total Gain Recognized | K27: Deferred Eligible Gain | L27: CA Principal Withholding
A29: 2025 | B29: 45930 | C29: =IF(A29=2025,$H$14,F28) | D29: =Assumptions!$D$18 | E29: =ROUND(C29*Installment_Rate*YEARFRAC(DATE(A29,1,1),B29,0),2) | F29: =MAX(0,C29-D29) | G29: =$H$15/$H$14 | H29: =ROUND(D29*G29,2) | I29: =IF(A29=2025,$H$16,0) | J29: =H29+I29 | K29: =MAX(0,$H$15-SUM($H$29:H29)) | L29: =ROUND(D29*CA_Withholding_Rate,2)
A30: 2026 | B30: 46295 | C30: =IF(A30=2025,$H$14,F29) | D30: =IF(A30=2034,F29,MIN(F29,Installment_Contract_Price/9)) | E30: =ROUND(C30*Installment_Rate*YEARFRAC(DATE(A30,1,1),B30,0),2) | F30: =MAX(0,C30-D30) | G30: =$H$15/$H$14 | H30: =ROUND(D30*G30,2) | I30: =IF(A30=2025,$H$16,0) | J30: =H30+I30 | K30: =MAX(0,$H$15-SUM($H$29:H30)) | L30: =ROUND(D30*CA_Withholding_Rate,2)
A31: 2027 | B31: 46660 | C31: =IF(A31=2025,$H$14,F30) | D31: =IF(A31=2034,F30,MIN(F30,Installment_Contract_Price/9)) | E31: =ROUND(C31*Installment_Rate*YEARFRAC(DATE(A31,1,1),B31,0),2) | F31: =MAX(0,C31-D31) | G31: =$H$15/$H$14 | H31: =ROUND(D31*G31,2) | I31: =IF(A31=2025,$H$16,0) | J31: =H31+I31 | K31: =MAX(0,$H$15-SUM($H$29:H31)) | L31: =ROUND(D31*CA_Withholding_Rate,2)
A32: 2028 | B32: 47026 | C32: =IF(A32=2025,$H$14,F31) | D32: =IF(A32=2034,F31,MIN(F31,Installment_Contract_Price/9)) | E32: =ROUND(C32*Installment_Rate*YEARFRAC(DATE(A32,1,1),B32,0),2) | F32: =MAX(0,C32-D32) | G32: =$H$15/$H$14 | H32: =ROUND(D32*G32,2) | I32: =IF(A32=2025,$H$16,0) | J32: =H32+I32 | K32: =MAX(0,$H$15-SUM($H$29:H32)) | L32: =ROUND(D32*CA_Withholding_Rate,2)
A33: 2029 | B33: 47391 | C33: =IF(A33=2025,$H$14,F32) | D33: =IF(A33=2034,F32,MIN(F32,Installment_Contract_Price/9)) | E33: =ROUND(C33*Installment_Rate*YEARFRAC(DATE(A33,1,1),B33,0),2) | F33: =MAX(0,C33-D33) | G33: =$H$15/$H$14 | H33: =ROUND(D33*G33,2) | I33: =IF(A33=2025,$H$16,0) | J33: =H33+I33 | K33: =MAX(0,$H$15-SUM($H$29:H33)) | L33: =ROUND(D33*CA_Withholding_Rate,2)
A34: 2030 | B34: 47756 | C34: =IF(A34=2025,$H$14,F33) | D34: =IF(A34=2034,F33,MIN(F33,Installment_Contract_Price/9)) | E34: =ROUND(C34*Installment_Rate*YEARFRAC(DATE(A34,1,1),B34,0),2) | F34: =MAX(0,C34-D34) | G34: =$H$15/$H$14 | H34: =ROUND(D34*G34,2) | I34: =IF(A34=2025,$H$16,0) | J34: =H34+I34 | K34: =MAX(0,$H$15-SUM($H$29:H34)) | L34: =ROUND(D34*CA_Withholding_Rate,2)
A35: 2031 | B35: 48121 | C35: =IF(A35=2025,$H$14,F34) | D35: =IF(A35=2034,F34,MIN(F34,Installment_Contract_Price/9)) | E35: =ROUND(C35*Installment_Rate*YEARFRAC(DATE(A35,1,1),B35,0),2) | F35: =MAX(0,C35-D35) | G35: =$H$15/$H$14 | H35: =ROUND(D35*G35,2) | I35: =IF(A35=2025,$H$16,0) | J35: =H35+I35 | K35: =MAX(0,$H$15-SUM($H$29:H35)) | L35: =ROUND(D35*CA_Withholding_Rate,2)
A36: 2032 | B36: 48487 | C36: =IF(A36=2025,$H$14,F35) | D36: =IF(A36=2034,F35,MIN(F35,Installment_Contract_Price/9)) | E36: =ROUND(C36*Installment_Rate*YEARFRAC(DATE(A36,1,1),B36,0),2) | F36: =MAX(0,C36-D36) | G36: =$H$15/$H$14 | H36: =ROUND(D36*G36,2) | I36: =IF(A36=2025,$H$16,0) | J36: =H36+I36 | K36: =MAX(0,$H$15-SUM($H$29:H36)) | L36: =ROUND(D36*CA_Withholding_Rate,2)
A37: 2033 | B37: 48852 | C37: =IF(A37=2025,$H$14,F36) | D37: =IF(A37=2034,F36,MIN(F36,Installment_Contract_Price/9)) | E37: =ROUND(C37*Installment_Rate*YEARFRAC(DATE(A37,1,1),B37,0),2) | F37: =MAX(0,C37-D37) | G37: =$H$15/$H$14 | H37: =ROUND(D37*G37,2) | I37: =IF(A37=2025,$H$16,0) | J37: =H37+I37 | K37: =MAX(0,$H$15-SUM($H$29:H37)) | L37: =ROUND(D37*CA_Withholding_Rate,2)
A38: 2034 | B38: 49217 | C38: =IF(A38=2025,$H$14,F37) | D38: =IF(A38=2034,F37,MIN(F37,Installment_Contract_Price/9)) | E38: =ROUND(C38*Installment_Rate*YEARFRAC(DATE(A38,1,1),B38,0),2) | F38: =MAX(0,C38-D38) | G38: =$H$15/$H$14 | H38: =ROUND(D38*G38,2) | I38: =IF(A38=2025,$H$16,0) | J38: =H38+I38 | K38: =MAX(0,$H$15-SUM($H$29:H38)) | L38: =ROUND(D38*CA_Withholding_Rate,2)

Sheet Equity Transfer
A1: ADC Fairfax & 3rd Disposal Tax Model — Partnership Interest Transfer
A2: ADC Fairfax Retail Partners LP interest transfer | Sections 741, 751, 752, 1446(f), and FIRPTA review.
A10: Amount Realized
A11: Line | B11: Item | C11: Tax Rule | D11: Book / Deal Amount | E11: Tax Adjustment | F11: Tax Amount | G11: Character % | H11: Result | I11: Status / Conclusion
A12: 1 | B12: Cash equity consideration | C12: IRC section 741 | D12: =Cash_Equity_Consideration | F12: =D12+E12
A13: 2 | B13: Debt relief | C13: IRC section 752 | D13: =Assumed_Liabilities | F13: =D13+E13
A14: 3 | B14: Total amount realized | C14: IRC sections 741 and 752 | D14: =D12+D13 | F14: =D14+E14
A18: Outside Basis
A19: Line | B19: Item | C19: Tax Rule | D19: Book / Deal Amount | E19: Tax Adjustment | F19: Tax Amount | G19: Character % | H19: Result | I19: Status / Conclusion
B20: Outside equity basis | C20: Partner tax basis | D20: 17884360 | H20: =D20
A27: Section 751 Hot-Asset Analysis
A28: Line | B28: Item | C28: Tax Rule | D28: Book / Deal Amount | E28: Tax Adjustment | F28: Tax Amount | G28: Character % | H28: Result | I28: Status / Conclusion
B31: Section 751 ordinary income | C31: IRC section 751 | G31: =IF($H$36=0,0,H31/$H$36) | H31: =Assumptions!$D$26+383050.20 | I31: Review — hot-asset support
B32: Section 741 capital gain | C32: IRC section 741 | G32: =IF($H$36=0,0,H32/$H$36) | H32: =H36-H31 | I32: Pass — residual capital gain
B36: Total partnership-interest gain | H36: =ROUND(D14-D20,2) | I36: Anchor: $10,850,640.00
A41: Withholding and Controlling-Interest Review
A42: Line | B42: Item | C42: Tax Rule | D42: Book / Deal Amount | E42: Tax Adjustment | F42: Tax Amount | G42: Character % | H42: Result | I42: Status / Conclusion
A43: 1 | B43: Foreign seller status | C43: IRC section 1446(f) | D43: Domestic | I43: Review — confirm seller status
A44: 2 | B44: FIRPTA withholding | C44: IRC section 1445 | D44: Not assumed | I44: Review — counsel confirmation
A45: 3 | B45: Controlling-interest transfer | C45: California / LA declaration | D45: Yes | I45: Review — more-than-50% control
A46: 4 | B46: Documentary transfer tax | C46: LA County declaration | D46: =LA_DTT_Exposure | I46: Review — assess county and city tax
A47: 5 | B47: Inside vs outside basis | C47: IRC sections 741 and 751 | D47: Review | I47: Review — reconcile schedules
A48: 6 | B48: Partnership tax filing | C48: IRC section 701 | D48: Pass-through | I48: Pass — partnership does not pay federal income tax
A49: 7 | B49: Buyer withholding certificate | C49: IRC section 1446(f) | D49: Pending | I49: Review — obtain before closing
A50: 8 | B50: Legal entity name | C50: Legal entity register | D50: ADC Fairfax Retail Partners LP | I50: Pass

Sheet LA Transfer Tax
A1: ADC Fairfax & 3rd Disposal Tax Model — Los Angeles Documentary Transfer Tax
A2: Countywide and City of Los Angeles documentary transfer tax on direct deed and greater-than-50% controlling-interest scenarios.
A10: Direct Transfer Calculation
A11: Scenario | B11: Jurisdiction | C11: Gross Consideration / FMV | D11: Liens Remaining | E11: Taxable Consideration | F11: Transfer Tax | G11: Rate per $1,000 | H11: Authority / Form Field | I11: Exemption Reason
A12: Direct Deed Transfer | B12: Los Angeles County | C12: =Gross_Sale_Price | D12: =Debt_Remaining | E12: =MAX(0,C12-D12) | F12: =ROUND(E12/1000*G12,2) | G12: 1.1 | H12: Los Angeles County declaration
A13: Direct Deed Transfer | B13: City of Los Angeles | C13: =Gross_Sale_Price | D13: =Debt_Remaining | E13: =MAX(0,C13-D13) | F13: =ROUND(E13/1000*G13,2) | G13: 4.5 | H13: Los Angeles County declaration
A21: Controlling-Interest Calculation
A22: Scenario | B22: Jurisdiction | C22: Gross Consideration / FMV | D22: Liens Remaining | E22: Taxable Consideration | F22: Transfer Tax | G22: Rate per $1,000 | H22: Authority / Form Field | I22: Exemption Reason
A23: Greater-than-50% Controlling-Interest Change | B23: Los Angeles County | C23: =Gross_Sale_Price | D23: =Debt_Remaining | E23: =MAX(0,C23-D23) | F23: =ROUND(E23/1000*G23,2) | G23: 1.1 | H23: Controlling-interest question on declaration
A24: Greater-than-50% Controlling-Interest Change | B24: City of Los Angeles | C24: =Gross_Sale_Price | D24: =Debt_Remaining | E24: =MAX(0,C24-D24) | F24: =ROUND(E24/1000*G24,2) | G24: 4.5 | H24: Controlling-interest question on declaration
A27: Direct deed combined exposure | F27: =SUM(F12:F13)
A28: Controlling-interest combined exposure | F28: =SUM(F23:F24)
A32: Rate Reference Table
A33: Jurisdiction | B33: County / City | C33: Rate per $1,000 | D33: Source | E33: Use in Base Case
A34: Los Angeles County | B34: Countywide | C34: 1.1 | D34: Los Angeles County declaration | E34: Yes
A35: Los Angeles | B35: City | C35: 4.5 | D35: Los Angeles County declaration | E35: Yes
A36: Culver City | B36: City | C36: 4.5 | D36: Los Angeles County declaration | E36: No
A37: Pomona / Redondo Beach | B37: City | C37: 2.2 | D37: Los Angeles County declaration | E37: No
A38: Santa Monica | B38: City | C38: 3 | D38: Los Angeles County declaration | E38: No

Sheet Sources & Controls
A1: ADC Fairfax & 3rd Disposal Tax Model — Sources & Controls
A2: Source hierarchy, cross-file anchors, tie-out controls, public-company context, and reviewer sign-off.
A8: External Source Register
A9: Control ID | B9: Type | C9: Description | D9: Expected | E9: Actual | F9: Variance | G9: Status | H9: Owner | I9: Reviewed Date | J9: Source Link
A10: SRC-01 | B10: Source | C10: Agree Realty 2024 Annual Report | G10: Review | H10: Elena Brooks | I10: 45922 | J10: sources/Agree_Realty_2024_Annual_Report.pdf
A11: SRC-02 | B11: Source | C11: Realty Income Q3 2024 disposition disclosure | G11: Review | H11: Elena Brooks | I11: 45922 | J11: sources/Realty_Income_2024_Q3_Earnings_Dispositions.pdf
A12: SRC-03 | B12: Source | C12: Los Angeles documentary transfer tax declaration | G12: Review | H12: Priya Raman | I12: 45922 | J12: sources/Los_Angeles_Declaration_Documentary_Transfer_Tax.pdf
A18: Calculation Tie-out Controls
A19: Control ID | B19: Type | C19: Description | D19: Expected | E19: Actual | F19: Variance | G19: Status | H19: Owner | I19: Reviewed Date | J19: Source Link
A20: TIE-01 | B20: Cross-file anchor | C20: Direct-sale total federal taxable gain | D20: 9820196.5 | E20: =Direct_Sale_Total_Gain | F20: =IF(OR(D20="",E20=""),"",ROUND(E20-D20,2)) | G20: =IF(F20="","Review",IF(ABS(F20)<0.01,"Pass","FAIL")) | H20: Sarah Chen, CPA | I20: 45922
A21: TIE-02 | B21: Cross-file anchor | C21: Section 1245 ordinary recapture | D21: 1107955 | E21: =Section_1245_Recapture | F21: =IF(OR(D21="",E21=""),"",ROUND(E21-D21,2)) | G21: =IF(F21="","Review",IF(ABS(F21)<0.01,"Pass","FAIL")) | H21: Sarah Chen, CPA | I21: 45922
A22: TIE-03 | B22: Cross-file anchor | C22: Section 291 ordinary income | D22: 865724.8 | E22: =Section_291_Income | F22: =IF(OR(D22="",E22=""),"",ROUND(E22-D22,2)) | G22: =IF(F22="","Review",IF(ABS(F22)<0.01,"Pass","FAIL")) | H22: Sarah Chen, CPA | I22: 45922
A23: TIE-04 | B23: Cross-file anchor | C23: Unrecaptured section 1250 gain | D23: 3462899.2 | E23: =Unrecaptured_1250_Gain | F23: =IF(OR(D23="",E23=""),"",ROUND(E23-D23,2)) | G23: =IF(F23="","Review",IF(ABS(F23)<0.01,"Pass","FAIL")) | H23: Sarah Chen, CPA | I23: 45922
A24: TIE-05 | B24: Cross-file anchor | C24: Residual section 1231 gain | D24: 4383617.5 | E24: =Residual_1231_Gain | F24: =IF(OR(D24="",E24=""),"",ROUND(E24-D24,2)) | G24: =IF(F24="","Review",IF(ABS(F24)<0.01,"Pass","FAIL")) | H24: Sarah Chen, CPA | I24: 45922
A25: TIE-06 | B25: Cross-file anchor | C25: Installment 2025 recognized gain | D25: 3935309 | E25: ='Installment Sale'!$J$29 | F25: =IF(OR(D25="",E25=""),"",ROUND(E25-D25,2)) | G25: =IF(F25="","Review",IF(ABS(F25)<0.01,"Pass","FAIL")) | H25: Sarah Chen, CPA | I25: 45922
A26: TIE-07 | B26: Cross-file anchor | C26: Installment deferred eligible gain | D26: 5884887.5 | E26: ='Installment Sale'!$K$29 | F26: =IF(OR(D26="",E26=""),"",ROUND(E26-D26,2)) | G26: =IF(F26="","Review",IF(ABS(F26)<0.01,"Pass","FAIL")) | H26: Sarah Chen, CPA | I26: 45922
A27: TIE-08 | B27: Cross-file anchor | C27: Partnership total gain | D27: 10850640 | E27: =Partnership_Total_Gain | F27: =IF(OR(D27="",E27=""),"",ROUND(E27-D27,2)) | G27: =IF(F27="","Review",IF(ABS(F27)<0.01,"Pass","FAIL")) | H27: Priya Raman | I27: 45922
A28: TIE-09 | B28: Cross-file anchor | C28: Section 751 ordinary income | D28: 1248775 | E28: ='Equity Transfer'!$H$31 | F28: =IF(OR(D28="",E28=""),"",ROUND(E28-D28,2)) | G28: =IF(F28="","Review",IF(ABS(F28)<0.01,"Pass","FAIL")) | H28: Priya Raman | I28: 45922
A29: TIE-10 | B29: Cross-file anchor | C29: Section 741 capital gain | D29: 9601865 | E29: ='Equity Transfer'!$H$32 | F29: =IF(OR(D29="",E29=""),"",ROUND(E29-D29,2)) | G29: =IF(F29="","Review",IF(ABS(F29)<0.01,"Pass","FAIL")) | H29: Priya Raman | I29: 45922
A30: TIE-11 | B30: Cross-file anchor | C30: Los Angeles DTT exposure | D30: 113736 | E30: =LA_DTT_Exposure | F30: =IF(OR(D30="",E30=""),"",ROUND(E30-D30,2)) | G30: =IF(F30="","Review",IF(ABS(F30)<0.01,"Pass","FAIL")) | H30: Priya Raman | I30: 45922
A31: TIE-12 | B31: Formula control | C31: Direct-sale character control | D31: 0 | E31: ='Direct Sale'!$I$44 | F31: =IF(OR(D31="",E31=""),"",ROUND(E31-D31,2)) | G31: =IF(F31="","Review",IF(ABS(F31)<0.01,"Pass","FAIL")) | H31: Priya Raman | I31: 45922
A42: Public-Company Context
A43: Agree Realty context | B43: Agree Realty Corporation (NYSE: ADC), based in Royal Oak, Michigan, had 2,370 properties across all 50 states, approximately 48.8 million square feet, and 99.6% occupancy at December 31, 2024.
A44: Disposition context | B44: Agree Realty invested approximately $951 million in 282 retail net-lease properties during 2024 and sold 26 properties for approximately $98.4 million of gross proceeds.
A45: Comparable benchmark | B45: Realty Income Corporation (NYSE: O) reported 15,457 properties, 98.7% occupancy, 92 properties sold in Q3 2024 for $249.5 million of net sales proceeds, and 214 properties sold in the first nine months for $451.4 million.
A46: Use limitation | B46: Fairfax & 3rd Retail Center and ADC Fairfax Retail Partners LP are modeled planning entities and are not represented as appearing in Agree Realty Corporation public filings.
A54: Review Sign-off
A55: Control ID | B55: Type | C55: Description | D55: Expected | E55: Actual | F55: Variance | G55: Status | H55: Owner | I55: Reviewed Date | J55: Source Link
A56: SIGN-01 | B56: Sign-off | C56: Tax planning specialist review | D56: Complete | G56: Review | H56: Sarah Chen, CPA | I56: 45922
A57: SIGN-02 | B57: Sign-off | C57: Treasury liquidity review | D57: Complete | G57: Review | H57: Michael Donovan | I57: 45923
A58: SIGN-03 | B58: Sign-off | C58: Legal and withholding review | D58: Pending | G58: Review | H58: Priya Raman | I58: 45924

Sheet Calc Draft
A1: ADC Fairfax & 3rd Disposal Tax Model — Calc Draft
A2: Hidden working sheet — not for reporting. Retains superseded gross-profit rounding and transfer-tax sensitivity checks.
A5: Draft ID | B5: Description | C5: Input 1 | D5: Input 2 | E5: Draft Result | F5: Final Reference | G5: Difference | H5: Disposition
A8: DRAFT-01 | B8: Superseded gross-profit rounding | C8: =Assumptions!$D$16 | D8: =Assumptions!$D$17 | E8: =ROUND(C8-D8,2) | F8: =Direct_Sale_Total_Gain | G8: =E8-F8 | H8: Superseded
A9: DRAFT-02 | B9: Transfer-tax sensitivity | C9: =Assumptions!$D$16 | D9: =Assumptions!$D$17 | E9: =ROUND(C9-D9,2) | F9: =Direct_Sale_Total_Gain | G9: =E9-F9 | H9: Superseded
A10: DRAFT-03 | B10: Basis allocation check | C10: =Assumptions!$D$16 | D10: =Assumptions!$D$17 | E10: =ROUND(C10-D10,2) | F10: =Direct_Sale_Total_Gain | G10: =E10-F10 | H10: Superseded
A11: DRAFT-04 | B11: Superseded gross-profit rounding | C11: =Assumptions!$D$16 | D11: =Assumptions!$D$17 | E11: =ROUND(C11-D11,2) | F11: =Direct_Sale_Total_Gain | G11: =E11-F11 | H11: Superseded
A12: DRAFT-05 | B12: Transfer-tax sensitivity | C12: =Assumptions!$D$16 | D12: =Assumptions!$D$17 | E12: =ROUND(C12-D12,2) | F12: =Direct_Sale_Total_Gain | G12: =E12-F12 | H12: Superseded
A13: DRAFT-06 | B13: Basis allocation check | C13: =Assumptions!$D$16 | D13: =Assumptions!$D$17 | E13: =ROUND(C13-D13,2) | F13: =Direct_Sale_Total_Gain | G13: =E13-F13 | H13: Superseded
A14: DRAFT-07 | B14: Superseded gross-profit rounding | C14: =Assumptions!$D$16 | D14: =Assumptions!$D$17 | E14: =ROUND(C14-D14,2) | F14: =Direct_Sale_Total_Gain | G14: =E14-F14 | H14: Superseded
A15: DRAFT-08 | B15: Transfer-tax sensitivity | C15: =Assumptions!$D$16 | D15: =Assumptions!$D$17 | E15: =ROUND(C15-D15,2) | F15: =Direct_Sale_Total_Gain | G15: =E15-F15 | H15: Superseded
A16: DRAFT-09 | B16: Basis allocation check | C16: =Assumptions!$D$16 | D16: =Assumptions!$D$17 | E16: =ROUND(C16-D16,2) | F16: =Direct_Sale_Total_Gain | G16: =E16-F16 | H16: Superseded
A17: DRAFT-10 | B17: Superseded gross-profit rounding | C17: =Assumptions!$D$16 | D17: =Assumptions!$D$17 | E17: =ROUND(C17-D17,2) | F17: =Direct_Sale_Total_Gain | G17: =E17-F17 | H17: Superseded
A18: DRAFT-11 | B18: Transfer-tax sensitivity | C18: =Assumptions!$D$16 | D18: =Assumptions!$D$17 | E18: =ROUND(C18-D18,2) | F18: =Direct_Sale_Total_Gain | G18: =E18-F18 | H18: Superseded
A19: DRAFT-12 | B19: Basis allocation check | C19: =Assumptions!$D$16 | D19: =Assumptions!$D$17 | E19: =ROUND(C19-D19,2) | F19: =Direct_Sale_Total_Gain | G19: =E19-F19 | H19: Superseded
... A25: DRAFT-18 | B25: Basis allocation check | C25: =Assumptions!$D$16 | D25: =Assumptions!$D$17 | E25: =ROUND(C25-D25,2) | F25: =Direct_Sale_Total_Gain | G25: =E25-F25 | H25: Retained for review
